2020-08-26 16:27:13 | main | INFO | ------------------------------------- INIT ------------------------------------------------------------
2020-08-26 16:27:13 | main | INFO | CRAWLER STARTS
2020-08-26 16:27:13 | vendor_queue | WARNING | Sitemap Category url: https://www.hepsiburada.com/sitemaps/kategoriler/sitemap_1.xml
2020-08-26 16:27:14 | vendor_queue | INFO | Task Created For Vendor : hepsiburada with regular sitemap
2020-08-26 16:27:14 | vendor_queue | WARNING | Sitemap Category url: https://www.teknosa.com/medias/sys_master/sitemaps/sitemaps/1752952165/Category-tr-TRY.xml
2020-08-26 16:27:14 | product_queue | INFO | Task Created For Product : bilgisayar
2020-08-26 16:27:14 | GET_request_async | ERROR |  @@@@ ERROR IN ASYNCH REQUEST @@@@ MESSAGE : 
2020-08-26 16:27:14 | vendor_queue | INFO | Task Created For Vendor : teknosa with regular sitemap
2020-08-26 16:27:14 | vendor_queue | WARNING | Sitemap Category url: https://www.mediamarkt.com.tr/sitemap/sitemap-productlist.xml
2020-08-26 16:27:14 | product_queue | INFO | Task Created For Product : bilgisayar
2020-08-26 16:27:14 | product_queue | ERROR |  No product found with name bilgisayar 
2020-08-26 16:27:14 | product_queue | INFO | Task Created For Product : cep-telefonu
2020-08-26 16:27:14 | product_queue | ERROR |  No product found with name cep-telefonu 
2020-08-26 16:27:14 | product_queue | INFO | Task Created For Product : notebook
2020-08-26 16:27:14 | product_queue | ERROR |  No product found with name notebook 
2020-08-26 16:27:14 | product_queue | INFO | Task Created For Product : laptop
2020-08-26 16:27:14 | product_queue | ERROR |  No product found with name laptop 
2020-08-26 16:27:14 | product_queue | INFO |  Product Tasks are ended for teknosa  
2020-08-26 16:27:15 | vendor_queue | INFO | Task Created For Vendor : media_markt with regular sitemap
2020-08-26 16:27:15 | product_queue | INFO | Task Created For Product : bilgisayar
2020-08-26 16:27:15 | product_search_xml | INFO | Searching bilgisayar in sitemap XML 
2020-08-26 16:27:15 | product_queue | INFO | Task Created For Product : cep-telefonu
2020-08-26 16:27:15 | product_search_xml | INFO | Searching cep-telefonu in sitemap XML 
2020-08-26 16:27:15 | product_search_xml | WARNING |  <<< Reconstructed the product string as = cep-telefonu >>>
2020-08-26 16:27:15 | product_search_xml | ERROR |  <<< Reconstructed the product string but found none again :( >>>
2020-08-26 16:27:15 | product_queue | ERROR |  No product found with name cep-telefonu 
2020-08-26 16:27:15 | product_queue | INFO | Task Created For Product : notebook
2020-08-26 16:27:15 | product_search_xml | INFO | Searching notebook in sitemap XML 
2020-08-26 16:27:15 | product_queue | INFO | Task Created For Product : laptop
2020-08-26 16:27:15 | product_search_xml | INFO | Searching laptop in sitemap XML 
2020-08-26 16:27:15 | product_queue | INFO |  Product Tasks are started for : media_markt  
2020-08-26 16:27:15 | page_queue | INFO | media_marktPage queue, product : bilgisayar
2020-08-26 16:27:15 | page_queue | INFO | PAGE : https://www.mediamarkt.com.tr/tr/category/_bilgisayar-504925.html
2020-08-26 16:27:15 | page_queue | INFO | media_marktPage queue, product : notebook
2020-08-26 16:27:15 | page_queue | INFO | PAGE : https://www.mediamarkt.com.tr/tr/category/_notebook-504927.html
2020-08-26 16:27:15 | page_queue | INFO | media_marktPage queue, product : laptop
2020-08-26 16:27:15 | page_queue | INFO | PAGE : https://www.mediamarkt.com.tr/tr/category/_laptop-ram-639559.html
2020-08-26 16:27:16 | _invoke_callbacks | ERROR | exception calling callback for <Future at 0x24968d6e390 state=finished returned Response>
Traceback (most recent call last):
  File "C:\Program Files\Python37\lib\concurrent\futures\_base.py", line 324, in _invoke_callbacks
    callback(self)
  File "C:\Program Files\Python37\lib\asyncio\futures.py", line 362, in _call_set_state
    dest_loop.call_soon_threadsafe(_set_state, destination, source)
  File "C:\Program Files\Python37\lib\asyncio\base_events.py", line 733, in call_soon_threadsafe
    self._check_closed()
  File "C:\Program Files\Python37\lib\asyncio\base_events.py", line 480, in _check_closed
    raise RuntimeError('Event loop is closed')
RuntimeError: Event loop is closed
2020-08-26 16:27:17 | _invoke_callbacks | ERROR | exception calling callback for <Future at 0x2496619bb38 state=finished returned Response>
Traceback (most recent call last):
  File "C:\Program Files\Python37\lib\concurrent\futures\_base.py", line 324, in _invoke_callbacks
    callback(self)
  File "C:\Program Files\Python37\lib\asyncio\futures.py", line 362, in _call_set_state
    dest_loop.call_soon_threadsafe(_set_state, destination, source)
  File "C:\Program Files\Python37\lib\asyncio\base_events.py", line 733, in call_soon_threadsafe
    self._check_closed()
  File "C:\Program Files\Python37\lib\asyncio\base_events.py", line 480, in _check_closed
    raise RuntimeError('Event loop is closed')
RuntimeError: Event loop is closed
